<?xml version="1.0"?>

<robot name="urdf_example">

  <link name="link1">
    <visual>
      <geometry>
        <box size= "0.1 0.1 0.5" />
      </geometry>
      <material name= "blue">
        <color rgba= "0 0 1 1"/>
      </material>
    </visual>
  </link>
  
  <link name="link2">
    <visual>
      <geometry>
        <box size= "0.1 0.1 2.0" />
      </geometry>
      <material name= "green">
        <color rgba= "0 1 0 1"/>
      </material>
    </visual>
  </link>
  
  <link name="link3"/> <!-- Allows for double rotation -->
  
  
  <joint name="joint1" type="revolute" >
    <parent link = "link1" />
    <child link = "link3" /> 
    <origin xyz = "0 0 0" rpy = "0 0 0" />
    <axis xyz= "0 1 0" /> <!-- Allows for double rotation - Y -->
    <limit effort="1000" velocity="3.0" />
  </joint>
  
  <joint name="joint2" type="revolute" >
    <parent link = "link3" />
    <child link = "link2" />
    <origin xyz = "1 0 0" rpy = "0 1.57 0" />
    <axis xyz= "0 0 1" /> <!-- Allows for double rotation - Z -->
    <limit effort="1000" velocity="3.0" /> <!-- Relevant to Gazebo -->
  </joint>
  
</robot>
